[ ] fix pyflakes

Error detected while processing function <SNR>41_RunPyflakes:
line   50:
Traceback (most recent call last):
  File "<string>", line 1, in <module>
  File "<string>", line 84, in check
  File "/usr/local/Cellar/python/2.7.11/Frameworks/Python.framework/Versions/2.7/lib/python2.7/site-packages/pyflakes/checker.py", line 253, in __init__
    self.handleChildren(tree)
  File "/usr/local/Cellar/python/2.7.11/Frameworks/Python.framework/Versions/2.7/lib/python2.7/site-packages/pyflakes/checker.py", line 520, in handleChildren
    self.handleNode(node, tree)
  File "/usr/local/Cellar/python/2.7.11/Frameworks/Python.framework/Versions/2.7/lib/python2.7/site-packages/pyflakes/checker.py", line 555, in handleNode
    handler(node)
  File "/usr/local/Cellar/python/2.7.11/Frameworks/Python.framework/Versions/2.7/lib/python2.7/site-packages/pyflakes/checker.py", line 702, in FUNCTIONDEF
    self.LAMBDA(node)
  File "/usr/local/Cellar/python/2.7.11/Frameworks/Python.framework/Versions/2.7/lib/python2.7/site-packages/pyflakes/checker.py", line 722, in LAMBDA
    for arg in node.args.args + node.args.kwonlyargs:
AttributeError: 'arguments' object has no attribute 'kwonlyargs'
Press ENTER or type command to continue
